<?xml version="1.0" encoding="utf-8"?>
<!-- This URDF was automatically created by SolidWorks to URDF Exporter! Originally created by Stephen Brawner (brawner@gmail.com) 
     Commit Version: 1.6.0-1-g15f4949  Build Version: 1.6.7594.29634
     For more information, please see http://wiki.ros.org/sw_urdf_exporter -->
<robot
  name="robot_description">
  <link
    name="base_link">
    <inertial>
      <origin
        xyz="0.0035754 -1.518E-09 0.05893"
        rpy="0 0 0" />
      <mass
        value="0.33865" />
      <inertia
        ixx="0.00089067"
        ixy="1.0848E-09"
        ixz="8.0631E-12"
        iyy="0.00089441"
        iyz="-3.7721E-13"
        izz="0.0017779" />
    </inertial>
    <visual>
      <origin
        xyz="0 0 0"
        rpy="0 0 0" />
      <geometry>
        <mesh
          filename="package://robot_description/meshes/base_link.STL" />
      </geometry>
      <material
        name="">
        <color
          rgba="0.79216 0.81961 0.93333 1" />
      </material>
    </visual>
    <collision>
      <origin
        xyz="0 0 0"
        rpy="0 0 0" />
      <geometry>
        <mesh
          filename="package://robot_description/meshes/base_link.STL" />
      </geometry>
    </collision>
  </link>
  <link
    name="r_wheel">
    <inertial>
      <origin
        xyz="-5.8816E-06 -0.013217 6.9219E-06"
        rpy="0 0 0" />
      <mass
        value="0.044423" />
      <inertia
        ixx="2.0144E-05"
        ixy="-2.1565E-10"
        ixz="-7.2576E-09"
        iyy="3.5561E-05"
        iyz="-1.0364E-10"
        izz="2.0144E-05" />
    </inertial>
    <visual>
      <origin
        xyz="0 0 0"
        rpy="0 0 0" />
      <geometry>
        <mesh
          filename="package://robot_description/meshes/r_wheel.STL" />
      </geometry>
      <material
        name="">
        <color
          rgba="0.79216 0.81961 0.93333 1" />
      </material>
    </visual>
    <collision>
      <origin
        xyz="0 0 0"
        rpy="0 0 0" />
      <geometry>
        <mesh
          filename="package://robot_description/meshes/r_wheel.STL" />
      </geometry>
    </collision>
  </link>
  <joint
    name="r_wheel_joint"
    type="continuous">
    <origin
      xyz="0.051833 -0.1085 0.02"
      rpy="0 0 0" />
    <parent
      link="base_link" />
    <child
      link="r_wheel" />
    <axis
      xyz="0 -1 0" />
  </joint>
  <link
    name="l_wheel">
    <inertial>
      <origin
        xyz="9.01458438498648E-06 0.0132166249702712 -1.11460776607009E-06"
        rpy="0 0 0" />
      <mass
        value="0.044422854949021" />
      <inertia
        ixx="2.01509333913829E-05"
        ixy="-3.18027235118427E-11"
        ixz="-2.83951902060619E-09"
        iyy="3.55612270238749E-05"
        iyz="2.37159316317813E-10"
        izz="2.0137574928078E-05" />
    </inertial>
    <visual>
      <origin
        xyz="0 0 0"
        rpy="0 0 0" />
      <geometry>
        <mesh
          filename="package://robot_description/meshes/l_wheel.STL" />
      </geometry>
      <material
        name="">
        <color
          rgba="0.792156862745098 0.819607843137255 0.933333333333333 1" />
      </material>
    </visual>
    <collision>
      <origin
        xyz="0 0 0"
        rpy="0 0 0" />
      <geometry>
        <mesh
          filename="package://robot_description/meshes/l_wheel.STL" />
      </geometry>
    </collision>
  </link>
  <joint
    name="l_wheel_joint"
    type="continuous">
    <origin
      xyz="0.051833 0.1085 0.02"
      rpy="0 0 0" />
    <parent
      link="base_link" />
    <child
      link="l_wheel" />
    <axis
      xyz="0 1 0" />
  </joint>
  <link
    name="camera_link">
    <inertial>
      <origin
        xyz="-0.0130484997995744 0.00024619675186878 -6.05673365648429E-05"
        rpy="0 0 0" />
      <mass
        value="0.0447522009689823" />
      <inertia
        ixx="2.72775274833716E-05"
        ixy="2.44341098323841E-07"
        ixz="-1.17396572383072E-09"
        iyy="3.94471808587631E-06"
        iyz="-2.80138997339365E-09"
        izz="2.73620912559789E-05" />
    </inertial>
    <visual>
      <origin
        xyz="0 0 0"
        rpy="0 0 0" />
      <geometry>
        <mesh
          filename="package://robot_description/meshes/camera_link.STL" />
      </geometry>
      <material
        name="">
        <color
          rgba="0.792156862745098 0.819607843137255 0.933333333333333 1" />
      </material>
    </visual>
    <collision>
      <origin
        xyz="0 0 0"
        rpy="0 0 0" />
      <geometry>
        <mesh
          filename="package://robot_description/meshes/camera_link.STL" />
      </geometry>
    </collision>
  </link>
  <joint
    name="camera_joint"
    type="fixed">
    <origin
      xyz="0.094783 0 0.0985"
      rpy="0 0 0" />
    <parent
      link="base_link" />
    <child
      link="camera_link" />
    <axis
      xyz="0 0 0" />
  </joint>
  <link
    name="base_laser">
    <inertial>
      <origin
        xyz="0 0 0"
        rpy="0 0 0" />
      <mass
        value="0" />
      <inertia
        ixx="0"
        ixy="0"
        ixz="0"
        iyy="0"
        iyz="0"
        izz="0" />
    </inertial>
    <visual>
      <origin
        xyz="0 0 0"
        rpy="0 0 0" />
      <geometry>
        <mesh
          filename="package://robot_description/meshes/base_laser.STL" />
      </geometry>
      <material
        name="">
        <color
          rgba="1 1 1 1" />
      </material>
    </visual>
    <collision>
      <origin
        xyz="0 0 0"
        rpy="0 0 0" />
      <geometry>
        <mesh
          filename="package://robot_description/meshes/base_laser.STL" />
      </geometry>
    </collision>
  </link>
  <joint
    name="base_laser"
    type="fixed">
    <origin
      xyz="0.037083276307275 0 0.152600000000001"
      rpy="0 0 0" />
    <parent
      link="base_link" />
    <child
      link="base_laser" />
    <axis
      xyz="0 0 0" />
  </joint>
</robot>